2024-07-22 10:35:29.311 | ERROR    | __main__:<module>:23 - An error has been caught in function '<module>', process 'MainProcess' (9804), thread 'MainThread' (5208):
Traceback (most recent call last):

> File "D:\mytest\UnittestDemo\logs\loguru_demo.py", line 23, in <module>
    Demo().my_function(1, 2, -3)
    └ <class '__main__.Demo'>

  File "D:\mytest\UnittestDemo\logs\loguru_demo.py", line 11, in my_function
    return 1 / (x + y + z)
                │   │   └ -3
                │   └ 2
                └ 1

ZeroDivisionError: division by zero
2024-07-22 11:21:31.199 | ERROR    | __main__:<module>:23 - An error has been caught in function '<module>', process 'MainProcess' (14168), thread 'MainThread' (7624):
Traceback (most recent call last):

> File "D:\mytest\UnittestDemo\logs\loguru_demo.py", line 23, in <module>
    Demo().my_function(1, 2, -3)
    └ <class '__main__.Demo'>

  File "D:\mytest\UnittestDemo\logs\loguru_demo.py", line 11, in my_function
    return 1 / (x + y + z)
                │   │   └ -3
                │   └ 2
                └ 1

ZeroDivisionError: division by zero
2024-07-22 11:23:56.381 | ERROR    | __main__:<module>:23 - An error has been caught in function '<module>', process 'MainProcess' (15964), thread 'MainThread' (15960):
Traceback (most recent call last):

> File "D:\mytest\UnittestDemo\logs\loguru_demo.py", line 23, in <module>
    Demo().my_function(1, 2, -3)
    └ <class '__main__.Demo'>

  File "D:\mytest\UnittestDemo\logs\loguru_demo.py", line 11, in my_function
    return 1 / (x + y + z)
                │   │   └ -3
                │   └ 2
                └ 1

ZeroDivisionError: division by zero
2024-07-22 11:24:11.400 | ERROR    | __main__:<module>:28 - An error has been caught in function '<module>', process 'MainProcess' (9372), thread 'MainThread' (12004):
Traceback (most recent call last):

> File "D:\mytest\UnittestDemo\logs\loguru_demo.py", line 28, in <module>
    Demo().my_function(1, 2, -3)
    └ <class '__main__.Demo'>

  File "D:\mytest\UnittestDemo\logs\loguru_demo.py", line 13, in my_function
    return 1 / (x + y + z)
                │   │   └ -3
                │   └ 2
                └ 1

ZeroDivisionError: division by zero
2024-07-22 11:30:52.093 | ERROR    | __main__:<module>:31 - An error has been caught in function '<module>', process 'MainProcess' (3060), thread 'MainThread' (8696):
Traceback (most recent call last):

> File "D:\mytest\UnittestDemo\logs\loguru_demo.py", line 31, in <module>
    Demo().my_function(1, 2, -3)
    └ <class '__main__.Demo'>

  File "D:\mytest\UnittestDemo\logs\loguru_demo.py", line 13, in my_function
    return 1 / (x + y + z)
                │   │   └ -3
                │   └ 2
                └ 1

ZeroDivisionError: division by zero
2024-07-22 11:31:15.761 | ERROR    | __main__:<module>:31 - An error has been caught in function '<module>', process 'MainProcess' (1796), thread 'MainThread' (13508):
Traceback (most recent call last):

> File "D:\mytest\UnittestDemo\logs\loguru_demo.py", line 31, in <module>
    Demo().my_function(1, 2, -3)
    └ <class '__main__.Demo'>

  File "D:\mytest\UnittestDemo\logs\loguru_demo.py", line 13, in my_function
    return 1 / (x + y + z)
                │   │   └ -3
                │   └ 2
                └ 1

ZeroDivisionError: division by zero
2024-07-22 11:31:25.668 | ERROR    | __main__:<module>:31 - An error has been caught in function '<module>', process 'MainProcess' (4752), thread 'MainThread' (9532):
Traceback (most recent call last):

> File "D:\mytest\UnittestDemo\logs\loguru_demo.py", line 31, in <module>
    Demo().my_function(1, 2, -3)
    └ <class '__main__.Demo'>

  File "D:\mytest\UnittestDemo\logs\loguru_demo.py", line 13, in my_function
    return 1 / (x + y + z)
                │   │   └ -3
                │   └ 2
                └ 1

ZeroDivisionError: division by zero
2024-07-22 11:31:28.801 | ERROR    | __main__:<module>:31 - An error has been caught in function '<module>', process 'MainProcess' (9120), thread 'MainThread' (8316):
Traceback (most recent call last):

> File "D:\mytest\UnittestDemo\logs\loguru_demo.py", line 31, in <module>
    Demo().my_function(1, 2, -3)
    └ <class '__main__.Demo'>

  File "D:\mytest\UnittestDemo\logs\loguru_demo.py", line 13, in my_function
    return 1 / (x + y + z)
                │   │   └ -3
                │   └ 2
                └ 1

ZeroDivisionError: division by zero
2024-07-22 11:31:38.087 | ERROR    | __main__:<module>:31 - An error has been caught in function '<module>', process 'MainProcess' (13128), thread 'MainThread' (2264):
Traceback (most recent call last):

> File "D:\mytest\UnittestDemo\logs\loguru_demo.py", line 31, in <module>
    Demo().my_function(1, 2, -3)
    └ <class '__main__.Demo'>

  File "D:\mytest\UnittestDemo\logs\loguru_demo.py", line 13, in my_function
    return 1 / (x + y + z)
                │   │   └ -3
                │   └ 2
                └ 1

ZeroDivisionError: division by zero
2024-07-22 11:31:47.484 | ERROR    | __main__:<module>:31 - An error has been caught in function '<module>', process 'MainProcess' (5632), thread 'MainThread' (6900):
Traceback (most recent call last):

> File "D:\mytest\UnittestDemo\logs\loguru_demo.py", line 31, in <module>
    Demo().my_function(1, 2, -3)
    └ <class '__main__.Demo'>

  File "D:\mytest\UnittestDemo\logs\loguru_demo.py", line 13, in my_function
    return 1 / (x + y + z)
                │   │   └ -3
                │   └ 2
                └ 1

ZeroDivisionError: division by zero
2024-07-22 15:38:16.392 | ERROR    | __main__:<module>:35 - An error has been caught in function '<module>', process 'MainProcess' (15680), thread 'MainThread' (1756):
Traceback (most recent call last):

> File "D:\mytest\UnittestDemo\logs\loguru_demo.py", line 35, in <module>
    Demo().my_function(1, 2, -3)
    └ <class '__main__.Demo'>

  File "D:\mytest\UnittestDemo\logs\loguru_demo.py", line 13, in my_function
    return 1 / (x + y + z)
                │   │   └ -3
                │   └ 2
                └ 1

ZeroDivisionError: division by zero
2024-07-22 15:38:16.393 | ERROR    | __main__:<module>:40 - 异常
Traceback (most recent call last):

> File "D:\mytest\UnittestDemo\logs\loguru_demo.py", line 38, in <module>
    main()
    └ <function main at 0x000001D6D2DB8A40>

  File "D:\mytest\UnittestDemo\logs\loguru_demo.py", line 17, in main
    raise RuntimeError("error...")

RuntimeError: error...
