2024-08-07 08:53:28.588 | ERROR    | unittest.case:_callTestMethod:589 - An error has been caught in function '_callTestMethod', process 'MainProcess' (18180), thread 'MainThread' (1512):
Traceback (most recent call last):

  File "D:\Users\Administrator\AppData\Local\Programs\Python\Python312\Lib\unittest\case.py", line 589, in _callTestMethod
    if method() is not None:
       └ <bound method TestDemo.test_catch_exception of <loguru_test_demo.TestDemo testMethod=test_catch_exception>>

  File "D:\mytest\UnittestDemo\testcase\loguru_test_demo.py", line 66, in test_catch_exception
    return 1 / 0

ZeroDivisionError: division by zero
2024-08-07 08:53:28.625 | INFO     | __main__:run_case:68 - 报告路径：D:\mytest\UnittestDemo\reports\result-20240807.html
2024-08-07 08:54:29.076 | ERROR    | unittest.case:_callTestMethod:589 - An error has been caught in function '_callTestMethod', process 'MainProcess' (5852), thread 'MainThread' (8076):
Traceback (most recent call last):

  File "D:\Users\Administrator\AppData\Local\Programs\Python\Python312\Lib\unittest\case.py", line 589, in _callTestMethod
    if method() is not None:
       └ <bound method TestDemo.test_catch_exception of <loguru_test_demo.TestDemo testMethod=test_catch_exception>>

  File "D:\mytest\UnittestDemo\testcase\loguru_test_demo.py", line 66, in test_catch_exception
    return 1 / 0

ZeroDivisionError: division by zero
2024-08-07 08:54:29.106 | INFO     | __main__:run_case:68 - 报告路径：D:\mytest\UnittestDemo\reports\result-20240807.html
2024-08-07 08:54:58.796 | ERROR    | unittest.case:_callTestMethod:589 - An error has been caught in function '_callTestMethod', process 'MainProcess' (11344), thread 'MainThread' (13996):
Traceback (most recent call last):

  File "D:\Users\Administrator\AppData\Local\Programs\Python\Python312\Lib\unittest\case.py", line 589, in _callTestMethod
    if method() is not None:
       └ <bound method TestDemo.test_catch_exception of <loguru_test_demo.TestDemo testMethod=test_catch_exception>>

  File "D:\mytest\UnittestDemo\testcase\loguru_test_demo.py", line 66, in test_catch_exception
    return 1 / 0

ZeroDivisionError: division by zero
2024-08-07 08:54:58.830 | INFO     | __main__:run_case:68 - 报告路径：D:\mytest\UnittestDemo\reports\result-20240807.html
2024-08-07 08:56:42.351 | ERROR    | unittest.case:_callTestMethod:589 - An error has been caught in function '_callTestMethod', process 'MainProcess' (12648), thread 'MainThread' (11148):
Traceback (most recent call last):

  File "D:\Users\Administrator\AppData\Local\Programs\Python\Python312\Lib\unittest\case.py", line 589, in _callTestMethod
    if method() is not None:
       └ <bound method TestDemo.test_catch_exception of <loguru_test_demo.TestDemo testMethod=test_catch_exception>>

  File "D:\mytest\UnittestDemo\testcase\loguru_test_demo.py", line 66, in test_catch_exception
    return 1 / 0

ZeroDivisionError: division by zero
2024-08-07 08:56:42.406 | INFO     | __main__:run_case:68 - 报告路径：D:\mytest\UnittestDemo\reports\result-20240807.html
2024-08-07 08:57:03.407 | ERROR    | unittest.case:_callTestMethod:589 - An error has been caught in function '_callTestMethod', process 'MainProcess' (9880), thread 'MainThread' (3568):
Traceback (most recent call last):

  File "D:\Users\Administrator\AppData\Local\Programs\Python\Python312\Lib\unittest\case.py", line 589, in _callTestMethod
    if method() is not None:
       └ <bound method TestDemo.test_catch_exception of <loguru_test_demo.TestDemo testMethod=test_catch_exception>>

  File "D:\mytest\UnittestDemo\testcase\loguru_test_demo.py", line 66, in test_catch_exception
    return 1 / 0

ZeroDivisionError: division by zero
2024-08-07 08:57:03.440 | INFO     | __main__:run_case:68 - 报告路径：D:\mytest\UnittestDemo\reports\result-20240807.html
2024-08-07 08:57:13.039 | ERROR    | unittest.case:_callTestMethod:589 - An error has been caught in function '_callTestMethod', process 'MainProcess' (18500), thread 'MainThread' (18516):
Traceback (most recent call last):

  File "D:\Users\Administrator\AppData\Local\Programs\Python\Python312\Lib\unittest\case.py", line 589, in _callTestMethod
    if method() is not None:
       └ <bound method TestDemo.test_catch_exception of <loguru_test_demo.TestDemo testMethod=test_catch_exception>>

  File "D:\mytest\UnittestDemo\testcase\loguru_test_demo.py", line 66, in test_catch_exception
    return 1 / 0

ZeroDivisionError: division by zero
2024-08-07 08:57:13.074 | INFO     | __main__:run_case:68 - 报告路径：D:\mytest\UnittestDemo\reports\result-20240807.html
2024-08-07 08:57:27.947 | ERROR    | unittest.case:_callTestMethod:589 - An error has been caught in function '_callTestMethod', process 'MainProcess' (14784), thread 'MainThread' (9248):
Traceback (most recent call last):

  File "D:\Users\Administrator\AppData\Local\Programs\Python\Python312\Lib\unittest\case.py", line 589, in _callTestMethod
    if method() is not None:
       └ <bound method TestDemo.test_catch_exception of <loguru_test_demo.TestDemo testMethod=test_catch_exception>>

  File "D:\mytest\UnittestDemo\testcase\loguru_test_demo.py", line 66, in test_catch_exception
    return 1 / 0

ZeroDivisionError: division by zero
2024-08-07 08:57:30.417 | INFO     | __main__:run_case:68 - 报告路径：D:\mytest\UnittestDemo\reports\result-20240807.html
2024-08-07 08:57:46.657 | ERROR    | unittest.case:_callTestMethod:589 - An error has been caught in function '_callTestMethod', process 'MainProcess' (11672), thread 'MainThread' (14964):
Traceback (most recent call last):

  File "D:\Users\Administrator\AppData\Local\Programs\Python\Python312\Lib\unittest\case.py", line 589, in _callTestMethod
    if method() is not None:
       └ <bound method TestDemo.test_catch_exception of <loguru_test_demo.TestDemo testMethod=test_catch_exception>>

  File "D:\mytest\UnittestDemo\testcase\loguru_test_demo.py", line 66, in test_catch_exception
    return 1 / 0

ZeroDivisionError: division by zero
2024-08-07 08:57:49.352 | INFO     | __main__:run_case:68 - 报告路径：D:\mytest\UnittestDemo\reports\result-20240807.html
2024-08-07 08:58:27.396 | ERROR    | unittest.case:_callTestMethod:589 - An error has been caught in function '_callTestMethod', process 'MainProcess' (15572), thread 'MainThread' (9832):
Traceback (most recent call last):

  File "D:\Users\Administrator\AppData\Local\Programs\Python\Python312\Lib\unittest\case.py", line 589, in _callTestMethod
    if method() is not None:
       └ <bound method TestDemo.test_catch_exception of <loguru_test_demo.TestDemo testMethod=test_catch_exception>>

  File "D:\mytest\UnittestDemo\testcase\loguru_test_demo.py", line 66, in test_catch_exception
    return 1 / 0

ZeroDivisionError: division by zero
2024-08-07 08:58:28.564 | INFO     | __main__:run_case:68 - 报告路径：D:\mytest\UnittestDemo\reports\result-20240807.html
2024-08-07 08:59:07.530 | ERROR    | unittest.case:_callTestMethod:589 - An error has been caught in function '_callTestMethod', process 'MainProcess' (268), thread 'MainThread' (17084):
Traceback (most recent call last):

  File "D:\Users\Administrator\AppData\Local\Programs\Python\Python312\Lib\unittest\case.py", line 589, in _callTestMethod
    if method() is not None:
       └ <bound method TestDemo.test_catch_exception of <loguru_test_demo.TestDemo testMethod=test_catch_exception>>

  File "D:\mytest\UnittestDemo\testcase\loguru_test_demo.py", line 66, in test_catch_exception
    return 1 / 0

ZeroDivisionError: division by zero
2024-08-07 08:59:15.865 | INFO     | __main__:run_case:68 - 报告路径：D:\mytest\UnittestDemo\reports\result-20240807.html
